<?xml version="1.0" encoding="UTF-8"?>
<!-- Generated by org.testng.reporters.JUnitReportReporter -->
<testsuite skipped="0" hostname="LAPTOP-AG8IO77N" name="com.cucumber.runner.TestRunnerDemo" tests="2" failures="0" timestamp="05 Jan 2018 01:48:04 GMT" time="0.889" errors="1">
  <testcase name="test" time="0.001" classname="com.cucumber.runner.TestRunnerDemo"/>
  <testcase name="feature" time="0.888" classname="com.cucumber.runner.TestRunnerDemo">
    <error type="cucumber.runtime.CucumberException" message="java.lang.AssertionError: Failure: I was expecting 1 to be equal to 2 expected [true] but found [false]
Reproduction Seed: ...
Country: ...">
      <![CDATA[cucumber.runtime.CucumberException: java.lang.AssertionError: Failure: I was expecting 1 to be equal to 2 expected [true] but found [false]Reproduction Seed: ...Country: ...at cucumber.api.testng.TestNGCucumberRunner.runCucumber(TestNGCucumberRunner.java:69)at cucumber.api.testng.AbstractTestNGCucumberTests.feature(AbstractTestNGCucumberTests.java:21)at sun.reflect.NativeMethodAccessorImpl.invoke0(Native Method)at sun.reflect.NativeMethodAccessorImpl.invoke(NativeMethodAccessorImpl.java:62)at sun.reflect.DelegatingMethodAccessorImpl.invoke(DelegatingMethodAccessorImpl.java:43)at java.lang.reflect.Method.invoke(Method.java:498)at org.testng.internal.MethodInvocationHelper.invokeMethod(MethodInvocationHelper.java:124)at org.testng.internal.Invoker.invokeMethod(Invoker.java:571)at org.testng.internal.Invoker.invokeTestMethod(Invoker.java:707)at org.testng.internal.Invoker.invokeTestMethods(Invoker.java:979)at org.testng.internal.TestMethodWorker.invokeTestMethods(TestMethodWorker.java:125)at org.testng.internal.TestMethodWorker.run(TestMethodWorker.java:109)at org.testng.TestRunner.privateRun(TestRunner.java:648)at org.testng.TestRunner.run(TestRunner.java:505)at org.testng.SuiteRunner.runTest(SuiteRunner.java:455)at org.testng.SuiteRunner.runSequentially(SuiteRunner.java:450)at org.testng.SuiteRunner.privateRun(SuiteRunner.java:415)at org.testng.SuiteRunner.run(SuiteRunner.java:364)at org.testng.SuiteRunnerWorker.runSuite(SuiteRunnerWorker.java:52)at org.testng.SuiteRunnerWorker.run(SuiteRunnerWorker.java:84)at org.testng.TestNG.runSuitesSequentially(TestNG.java:1187)at org.testng.TestNG.runSuitesLocally(TestNG.java:1116)at org.testng.TestNG.runSuites(TestNG.java:1028)at org.testng.TestNG.run(TestNG.java:996)at org.apache.maven.surefire.testng.TestNGExecutor.run(TestNGExecutor.java:295)at org.apache.maven.surefire.testng.TestNGXmlTestSuite.execute(TestNGXmlTestSuite.java:84)at org.apache.maven.surefire.testng.TestNGProvider.invoke(TestNGProvider.java:90)at org.apache.maven.surefire.booter.ForkedBooter.invokeProviderInSameClassLoader(ForkedBooter.java:203)at org.apache.maven.surefire.booter.ForkedBooter.runSuitesInProcess(ForkedBooter.java:155)at org.apache.maven.surefire.booter.ForkedBooter.main(ForkedBooter.java:103)Caused by: java.lang.AssertionError: Failure: I was expecting 1 to be equal to 2 expected [true] but found [false]at org.testng.Assert.fail(Assert.java:96)at org.testng.Assert.failNotEquals(Assert.java:776)at org.testng.Assert.assertTrue(Assert.java:44)at com.cucumber.test.StepDefinitions.user_navigates_to_URL_with_excel_row_dataset(StepDefinitions.java:54)at âœ½.Given User navigates to URL with excel row "1" dataset(src/test/resources/login.feature:23)]]>
    </error>
  </testcase> <!-- feature -->
</testsuite> <!-- com.cucumber.runner.TestRunnerDemo -->
